Workbook
Name CountyDropDown: '[1]VA Program Limits'!$J$51:INDEX('[1]VA Program Limits'!$J$51:$J$183,COUNTIF('[1]VA Program Limits'!$J$51:$J$183,"?*"))
Name IncomeTable: 'Virginia Housing Limits'!$A$8:$H$15
Name RentTable: 'Virginia Housing Limits'!$B$21:$H$25
Name Sec8Limits: #REF!
Name VACounty: '[1]VA Program Limits'!$F$51:$F$183
Name VAMTSP: '[3]MTSP-HERA Limits-HIDE'!$C$1:$GO$136

Sheet Instructions
A2: Instructions: Complete all cells of the Rent and Occupanct Report as indicated by the definitions and instructions listed for each column and row. All nonself-populating cells must be filled with the appropriate response for the particular row and column. Please submit the completed report to Rachel Hightman at rachel.hightman2@rva.gov as an excel workbook.
A4: Column: | B4: =SUBSTITUTE(ADDRESS(1, MATCH("Unit #", 'Rent and Occupancy Report'!22:22, 0), 4), "1", "") -> A | C4: "Unit #" - The unit number | E4: Row: | F4: =MATCH("Date", 'Rent and Occupancy Report'!A:A, 0) -> 3 | G4: "Date" - Date the report is submitted.
A6: Column: | B6: =SUBSTITUTE(ADDRESS(1, MATCH("No. of Bedrooms", 'Rent and Occupancy Report'!22:22, 0), 4), "1", "") -> B | C6: "No. of Bedrooms" - List the number of bedrooms, please type '0' for efficiency/zero-bedroom units. (i.g. 0, 1, 2, 3, 4) | E6: Row: | F6: =MATCH("Reporting Period", 'Rent and Occupancy Report'!A:A, 0) -> 4 | G6: "Reporting Period" - The period being reported on (05/16/2024 - 05/15/2025). This period reflect the limits set by Virginia Housing Limits as of April 1, 2024. 2024 limits were effective April 1, 2024 and must have been implemented by 5/16/2024. 2025 limits were effective April 1, 2025 and must have been implemented by 5/16/2025
A8: Column: | B8: =SUBSTITUTE(ADDRESS(1, MATCH("% of AMI Unit Designation", 'Rent and Occupancy Report'!22:22, 0), 4), "1", "") -> C | C8: "% of AMI Unit Designation" - Please base this on the Affordable Housing Performance Grant Agreement per Exhibit A. Percents written should be written in increments of 10 (i.g. 20, 30, 40, 50, 60, 70, 80) | E8: Row: | F8: =MATCH("Property Owner", 'Rent and Occupancy Report'!A:A, 0) -> 6 | G8: "Property Owner" - The name of the owner or owner entity of the property.
A10: Column: | B10: =SUBSTITUTE(ADDRESS(1, MATCH("Rent Amount", 'Rent and Occupancy Report'!22:22, 0), 4), "1", "") -> D | C10: "Rent Amount" - The monthly rent amount per the lease agreement. | E10: Row: | F10: =MATCH("Property Contact (Phone)", 'Rent and Occupancy Report'!A:A, 0) -> 7 | G10: "Property Contact (Phone)" - The phone number of the person completing the report.
A12: Column: | B12: =SUBSTITUTE(ADDRESS(1, MATCH("Tenant(s) Name(s)", 'Rent and Occupancy Report'!22:22, 0), 4), "1", "") -> E | C12: "Tenant(s) Name(s)" - All persons named on the lease agreement. | E12: Row: | F12: =MATCH("Property Contact (Email)", 'Rent and Occupancy Report'!A:A, 0) -> 8 | G12: "Property Contact (Email)" - The email of the person completing the report.
A14: Column: | B14: =SUBSTITUTE(ADDRESS(1, MATCH("Household Size", 'Rent and Occupancy Report'!22:22, 0), 4), "1", "") -> F | C14: "Household Size" - Number of persons residing in the home, including those under 18 years of age. | E14: Row: | F14: =MATCH("Property", 'Rent and Occupancy Report'!A:A, 0) -> 9 | G14: "Property" - The name of the property.
A16: Column: | B16: =SUBSTITUTE(ADDRESS(1, MATCH("Annual (Gross) Income", 'Rent and Occupancy Report'!22:22, 0), 4), "1", "") -> G | C16: "Annual (Gross) Income" - Total gross income of all persons residing in the home at time of intial certification or recerification. | E16: Row: | F16: =MATCH("Recipient", 'Rent and Occupancy Report'!A:A, 0) -> 10 | G16: "Recipient" - The Recipient of the Affordable Housing Performance Grant as written in the Affordable Housing Performance Grant agreement, its assign or successor as authorized by the agreement.
A18: Column: | B18: =SUBSTITUTE(ADDRESS(1, MATCH("% of AMI", 'Rent and Occupancy Report'!22:22, 0), 4), "1", "") -> H | C18: "% of AMI" - This column is self-populated, and calculates the % of Area Median Income based on the Annual Gross Income and household size. | E18: Row: | F18: =MATCH("Address", 'Rent and Occupancy Report'!A:A, 0) -> 11 | G18: "Address" - The complete address of the property.
A20: Column: | B20: =SUBSTITUTE(ADDRESS(1, MATCH("Unit Designation Equal Occupancy?", 'Rent and Occupancy Report'!22:22, 0), 4), "1", "") -> I | C20: "Unit Designation Equal Occupancy?" - This column is self populated and verifies that the resident income is in alignment with the AMI designation for the unit. | E20: Row: | F20: =MATCH("Total Units", 'Rent and Occupancy Report'!A:A, 0) -> 13 | G20: "Total Units" - The total number of residential units in the property.
A22: Column: | B22: =SUBSTITUTE(ADDRESS(1, MATCH("Date of Last Income Certification or Re-certification", 'Rent and Occupancy Report'!22:22, 0), 4), "1", "") -> M | C22: "Date of Last Income Certification or Re-certification" - Income certifications and re-certifications should be updated annually by March 31 of the current year. Certifications for new move-ins must have been completed prior to the start of the inital lease period. | E22: Row: | F22: =MATCH("Total Certified Performance Units", 'Rent and Occupancy Report'!A:A, 0) -> 15 | G22: "Total Certified Performance Units" - The total number of afforable units as written in the Affordable Housing Performance Grant agreement.
A24: Column: | B24: =SUBSTITUTE(ADDRESS(1, MATCH("Income Certification Validation", 'Rent and Occupancy Report'!22:22, 0), 4), "1", "") -> N | C24: "Income Certification Validation" - This column is self-populated, and validates that the income certification was updated according the the certification and re-certification calendar. | E24: Row: | F24: =MATCH("0-50% AMI Rental Units", 'Rent and Occupancy Report'!A:A, 0) -> 16 | G24: "0-50% AMI Rental Units" - The number of units restricted to 0-50% AMI
A26: Column: | B26: =SUBSTITUTE(ADDRESS(1, MATCH("Virginia Housing Published Rent", 'Rent and Occupancy Report'!22:22, 0), 4), "1", "") -> O | C26: "Virginia Housing Published Rent"- The Virginia Housing Published Rent for the City of Richmond MSA as of April 1 of the reporting year. Project owners must implement the limits within 45 days from April 1. The new limits must be implemented and applied for all new move-ins and required annual recertifications by May 16 of the reporting year. | E26: Row: | F26: =MATCH("51-80% AMI Rental Units", 'Rent and Occupancy Report'!A:A, 0) -> 17 | G26: "51-80% AMI Rental Units" - The number of units restricted to 51-80% AMI.
A28: Column: | B28: =SUBSTITUTE(ADDRESS(1, MATCH("Utility Allowance", 'Rent and Occupancy Report'!22:22, 0), 4), "1", "") -> P | C28: "Utility Allowance"- If the tenant pays for their own utilities, the applicable Utility Allowance should be listed. In the comments column, the source of the Utility Allowance should be listed with the first unit. | E28: Row: | F28: =MATCH("Name", 'Rent and Occupancy Report'!A:A, 0) -> 19 | G28: "Name" - The name of the person completing the report.
A30: Column: | B30: =SUBSTITUTE(ADDRESS(1, MATCH("Maximum Allowed Rent", 'Rent and Occupancy Report'!22:22, 0), 4), "1", "") -> Q | C30: "Maximum Allowed Rent"- This column is self-populated, and equals the Virginia Housing published rent minus the applicable Utility Allowance. | E30: Row: | F30: =MATCH("Title", 'Rent and Occupancy Report'!A:A, 0) -> 20 | G30: "Title" - Title of the person completing the report.
A32: Column: | B32: =SUBSTITUTE(ADDRESS(1, MATCH("Tenant Portion of Rent", 'Rent and Occupancy Report'!22:22, 0), 4), "1", "") -> R | C32: "Tenant Portion of Rent"- If the tenant has a voucher, list the tenant portion here. If the tenant does not have a voucher, then please list the total rent.
A34: Column: | B34: =SUBSTITUTE(ADDRESS(1, MATCH("Subsidy Amount", 'Rent and Occupancy Report'!22:22, 0), 4), "1", "") -> S | C34: "Subsidy Amount"- If applicable, please list the subsidy amount.
A36: Column: | B36: =SUBSTITUTE(ADDRESS(1, MATCH("Gross Rent", 'Rent and Occupancy Report'!22:22, 0), 4), "1", "") -> T | C36: "Gross Rent"- This column is self-populated, and equals the tenant portion of rent plus the subsidy, if applicable.
A38: Column: | B38: =SUBSTITUTE(ADDRESS(1, MATCH("Unit in Compliance? (Y or N)", 'Rent and Occupancy Report'!22:22, 0), 4), "1", "") -> U | C38: "Unit in Compliance? (Y or N)"- This column is self-populated, and validates if the unit is in compliance with applicable rent and income limits.
A40: Column: | B40: =SUBSTITUTE(ADDRESS(1, MATCH("Subsidy Type", 'Rent and Occupancy Report'!22:22, 0), 4), "1", "") -> V | C40: "Subsidy Type"- The type of subsidy (e.g. project-based, individual housing choice voucher, etc.) should be listed in this column, if applicable.
A42: Column: | B42: =SUBSTITUTE(ADDRESS(1, MATCH("Comments", 'Rent and Occupancy Report'!22:22, 0), 4), "1", "") -> W | C42: "Comments"- This column can be used for any necessary comments, such as the source of the Utility Allowance.

Sheet Rent and Occupancy Report
A1: City of Richmond Rental Compliance Rent and Occupancy Report
A3: Date
A4: Reporting Period | B4: 5/16/2024-5/15/2025
D5: Performance Units in Compliance by AMI | H5: Performance Units Not in Compliance by AMI
A6: Property Owner | D6: 0.2 | E6: =IF(OR(COUNTIF($U$23:$U$500, "Y")=0), "", COUNTIFS($U$23:$U$500, "Y", $C$23:$C$500, "=20")) | F6: ="of " & IF(OR(COUNTIF( $C$23:$C$500, "=20")=0), 0, COUNTIF($C$23:$C$500, "=20")) -> of 0 | H6: 0.2 | I6: =IF(OR(COUNTIF($U$23:$U$500, "N")=0), "", COUNTIFS($U$23:$U$500, "N", $C$23:$C$500, "=20")) | J6: ="of " & IF(OR(COUNTIF( $C$23:$C$500, "=20")=0), 0, COUNTIF($C$23:$C$500, "=20")) -> of 0 | L6: Compliance Review
A7: Property Contact (Phone) | D7: 0.3 | E7: =IF(OR(COUNTIF($U$23:$U$500, "Y")=0), "", COUNTIFS($U$23:$U$500, "Y", $C$23:$C$500, "=30")) | F7: ="of " & IF(OR(COUNTIF( $C$23:$C$500, "=30")=0), 0, COUNTIF($C$23:$C$500, "=30")) -> of 0 | H7: 0.3 | I7: =IF(OR(COUNTIF($U$23:$U$500, "N")=0), "", COUNTIFS($U$23:$U$500, "N", $C$23:$C$500, "=30")) | J7: ="of " & IF(OR(COUNTIF( $C$23:$C$500, "=30")=0), 0, COUNTIF($C$23:$C$500, "=30")) -> of 0 | L7: Date HCD received from Developer:
A8: Property Contact (Email) | D8: 0.4 | E8: =IF(OR(COUNTIF($U$23:$U$500, "Y")=0), "", COUNTIFS($U$23:$U$500, "Y", $C$23:$C$500, "=40")) | F8: ="of "&IF(OR(COUNTIF($C$23:$C$500,"=40")=0),0,COUNTIF($C$23:$C$500,"=""40")) -> of 0 | H8: 0.4 | I8: =IF(OR(COUNTIF($U$23:$U$500, "N")=0), "", COUNTIFS($U$23:$U$500, "N", $C$23:$C$500, "=40")) | J8: ="of "&IF(OR(COUNTIF($C$23:$C$500,"=40")=0),0,COUNTIF($C$23:$C$500,"=""40")) -> of 0 | L8: Date of Completed Review:
A9: Property | D9: 0.5 | E9: =IF(OR(COUNTIF($U$23:$U$500, "Y")=0), "", COUNTIFS($U$23:$U$500, "Y", $C$23:$C$500, "=50")) | F9: ="of " & IF(OR(COUNTIF( $C$23:$C$500, "=50")=0), 0, COUNTIF($C$23:$C$500, "=50")) -> of 0 | H9: 0.5 | I9: =IF(OR(COUNTIF($U$23:$U$500, "N")=0), "", COUNTIFS($U$23:$U$500, "N", $C$23:$C$500, "=50")) | J9: ="of " & IF(OR(COUNTIF( $C$23:$C$500, "=50")=0), 0, COUNTIF($C$23:$C$500, "=50")) -> of 0 | L9: Reviewed By:
A10: Recipient | D10: 0.6 | E10: =IF(OR(COUNTIF($U$23:$U$500, "Y")=0), "", COUNTIFS($U$23:$U$500, "Y", $C$23:$C$500, "=60")) | F10: ="of " & IF(OR(COUNTIF( $C$23:$C$500, "=60")=0), 0, COUNTIF($C$23:$C$500, "=60")) -> of 0 | H10: 0.6 | I10: =IF(OR(COUNTIF($U$23:$U$500, "N")=0), "", COUNTIFS($U$23:$U$500, "N", $C$23:$C$500, "=60")) | J10: ="of " & IF(OR(COUNTIF( $C$23:$C$500, "=60")=0), 0, COUNTIF($C$23:$C$500, "=60")) -> of 0 | L10: Recommendation:
A11: Address | D11: 0.7 | E11: =IF(OR(COUNTIF($U$23:$U$500, "Y")=0), "", COUNTIFS($U$23:$U$500, "Y", $C$23:$C$500, "=70")) | F11: ="of " & IF(OR(COUNTIF( $C$23:$C$500, "=70")=0), 0, COUNTIF($C$23:$C$500, "=70")) -> of 0 | H11: 0.7 | I11: =IF(OR(COUNTIF($U$23:$U$500, "N")=0), "", COUNTIFS($U$23:$U$500, "N", $C$23:$C$500, "=70")) | J11: ="of " & IF(OR(COUNTIF( $C$23:$C$500, "=70")=0), 0, COUNTIF($C$23:$C$500, "=70")) -> of 0
D12: 0.8 | E12: =IF(OR(COUNTIF($U$23:$U$500, "Y")=0), "", COUNTIFS($U$23:$U$500, "Y", $C$23:$C$500, "=80")) | F12: ="of " & IF(OR(COUNTIF( $C$23:$C$500, "=80")=0), 0, COUNTIF($C$23:$C$500, "=80")) -> of 0 | H12: 0.8 | I12: =IF(OR(COUNTIF($U$23:$U$500, "N")=0), "", COUNTIFS($U$23:$U$500, "N", $C$23:$C$500, "=80")) | J12: ="of " & IF(OR(COUNTIF( $C$23:$C$500, "=80")=0), 0, COUNTIF($C$23:$C$500, "=80")) -> of 0
A13: Total Units | D13: Total | E13: =IF(OR(SUM(E6:E12)=0), "", SUM(E6:E12)) | F13: ="of " & B15 -> of 0 | H13: Total | I13: =IF(OR(SUM(I6:I12)=0), "", SUM(I6:I12)) | J13: ="of " & B15 -> of 0
A14: Total Performance Units | B14: =IF(OR(SUM(B16:B17)=0), "", SUM(B16:B17)) | D14: Average AMI | E14: {=IF(OR(E13=""),"",(SUMPRODUCT((E6:E12>0)*(D6:D12)*(E6:E12)) / SUMIFS(E6:E12, E6:E12, ">0") *100 & "%"))} | H14: Average AMI | I14: {=IF(OR(I13=""),"",(SUMPRODUCT((I6:I12>0)*(H6:H12)*(I6:I12)) / SUMIFS(I6:I12, I6:I12, ">0") *100 & "%"))}
A15: Total Certified Performance Units | B15: =COUNTIFS(M23:M501, ">0", C23:C501, "<=80", C23:C501, "<>") -> 0
A16: 0-50% AMI Rental Units | B16: =IF(OR(COUNTIF(C23:C501, "<=50")=0),"", COUNTIF(C23:C501, "<=50"))
A17: 51-80% AMI Rental Units | B17: =IF(OR(COUNTIFS(C23:C501, ">=51", C23:C501, "<=80")=0), "", COUNTIFS(C23:C501, ">=51", C23:C501, "<=80"))
A19: Name
A20: Title
A22: Unit # | B22: No. of Bedrooms | C22: % of AMI Unit Designation | D22: Rent Amount | E22: Tenant(s) Name(s) | F22: Household Size | G22: Annual (Gross) Income | H22: % of AMI | I22: Unit Designation Equal Occupancy? | J22: Lease Period Start | K22: Lease Period End | L22: New move-in? (Y or N) | M22: Date of Last Income Certification or Re-certification | N22: Income Certification Validation | O22: Virginia Housing Published Rent | P22: Utility Allowance | Q22: Maximum Allowed Rent | R22: Tenant Portion of Rent | S22: Subsidy Amount | T22: Gross Rent | U22: Unit in Compliance? (Y or N) | V22: Subsidy Type | W22: Comments
H23: {=IF(OR(F23="", G23=""), "", _xlfn.LET( _xlpm.rowIndex, MATCH(F23, INDEX(IncomeTable,,1), 0), _xlpm.thresholds, INDEX(IncomeTable, _xlpm.rowIndex, 2):INDEX(IncomeTable, _xlpm.rowIndex, 8), _xlpm.labels, {20,30,40,50,60,70,80}, _xlpm.income, G23, IF(_xlpm.income < INDEX(_xlpm.thresholds,1), "Below 20%", IF(_xlpm.income > INDEX(_xlpm.thresholds,7), "Above 80%", INDEX(_xlpm.labels, _xlfn.XLOOKUP(_xlpm.income, _xlpm.thresholds, _xlfn.SEQUENCE(1,7), , -1)) ) ) ) )} | I23: =IF(AND(ISNUMBER(C23), ISNUMBER(H23)), IF(C23=H23, "Y", "N"), "") | N23: =IF(OR(L23="",M23="",J23=""),"", IF(L23="Y", IF(M23<=J23,"Y","N"), IF(M23<=DATE(YEAR(J23),3,31),"Y","N") )) | O23: =IF(OR(C23="", B23=""), "", INDEX(RentTable, MATCH(B23, {0,1,2,3,4}, 0), MATCH(C23, {20,30,40,50,60,70,80}, 1)) ) | Q23: =IF(OR(O23="", ISBLANK(O23), O23=0), "", O23 - P23) | T23: =IF(OR(R23=""), "", R23 + S23) | U23: {=_xlfn.IFS(OR(Q23="", T23="", Q23=0, "", T23=0), "", AND(T23<=Q23,D23<=Q23), "Y", OR(T23>Q23,D23>Q23), "N")}
H24: {=IF(OR(F24="", G24=""), "", _xlfn.LET( _xlpm.rowIndex, MATCH(F24, INDEX(IncomeTable,,1), 0), _xlpm.thresholds, INDEX(IncomeTable, _xlpm.rowIndex, 2):INDEX(IncomeTable, _xlpm.rowIndex, 8), _xlpm.labels, {20,30,40,50,60,70,80}, _xlpm.income, G24, IF(_xlpm.income < INDEX(_xlpm.thresholds,1), "Below 20%", IF(_xlpm.income > INDEX(_xlpm.thresholds,7), "Above 80%", INDEX(_xlpm.labels, _xlfn.XLOOKUP(_xlpm.income, _xlpm.thresholds, _xlfn.SEQUENCE(1,7), , -1)) ) ) ) )} | I24: =IF(AND(ISNUMBER(C24), ISNUMBER(H24)), IF(C24=H24, "Y", "N"), "") | N24: =IF(OR(L24="",M24="",J24=""),"", IF(L24="Y", IF(M24<=J24,"Y","N"), IF(M24<=DATE(YEAR(J24),3,31),"Y","N") )) | O24: =IF(OR(C24="", B24=""), "", INDEX(RentTable, MATCH(B24, {0,1,2,3,4}, 0), MATCH(C24, {20,30,40,50,60,70,80}, 1)) ) | Q24: =IF(OR(O24="", ISBLANK(O24), O24=0), "", O24 - P24) | T24: =IF(OR(R24=""), "", R24 + S24) | U24: {=_xlfn.IFS(OR(Q24="", T24="", Q24=0, "", T24=0), "", AND(T24<=Q24,D24<=Q24), "Y", OR(T24>Q24,D24>Q24), "N")}
H25: {=IF(OR(F25="", G25=""), "", _xlfn.LET( _xlpm.rowIndex, MATCH(F25, INDEX(IncomeTable,,1), 0), _xlpm.thresholds, INDEX(IncomeTable, _xlpm.rowIndex, 2):INDEX(IncomeTable, _xlpm.rowIndex, 8), _xlpm.labels, {20,30,40,50,60,70,80}, _xlpm.income, G25, IF(_xlpm.income < INDEX(_xlpm.thresholds,1), "Below 20%", IF(_xlpm.income > INDEX(_xlpm.thresholds,7), "Above 80%", INDEX(_xlpm.labels, _xlfn.XLOOKUP(_xlpm.income, _xlpm.thresholds, _xlfn.SEQUENCE(1,7), , -1)) ) ) ) )} | I25: =IF(AND(ISNUMBER(C25), ISNUMBER(H25)), IF(C25=H25, "Y", "N"), "") | N25: =IF(OR(L25="",M25="",J25=""),"", IF(L25="Y", IF(M25<=J25,"Y","N"), IF(M25<=DATE(YEAR(J25),3,31),"Y","N") )) | O25: =IF(OR(C25="", B25=""), "", INDEX(RentTable, MATCH(B25, {0,1,2,3,4}, 0), MATCH(C25, {20,30,40,50,60,70,80}, 1)) ) | Q25: =IF(OR(O25="", ISBLANK(O25), O25=0), "", O25 - P25) | T25: =IF(OR(R25=""), "", R25 + S25) | U25: {=_xlfn.IFS(OR(Q25="", T25="", Q25=0, "", T25=0), "", AND(T25<=Q25,D25<=Q25), "Y", OR(T25>Q25,D25>Q25), "N")}
H26: {=IF(OR(F26="", G26=""), "", _xlfn.LET( _xlpm.rowIndex, MATCH(F26, INDEX(IncomeTable,,1), 0), _xlpm.thresholds, INDEX(IncomeTable, _xlpm.rowIndex, 2):INDEX(IncomeTable, _xlpm.rowIndex, 8), _xlpm.labels, {20,30,40,50,60,70,80}, _xlpm.income, G26, IF(_xlpm.income < INDEX(_xlpm.thresholds,1), "Below 20%", IF(_xlpm.income > INDEX(_xlpm.thresholds,7), "Above 80%", INDEX(_xlpm.labels, _xlfn.XLOOKUP(_xlpm.income, _xlpm.thresholds, _xlfn.SEQUENCE(1,7), , -1)) ) ) ) )} | I26: =IF(AND(ISNUMBER(C26), ISNUMBER(H26)), IF(C26=H26, "Y", "N"), "") | N26: =IF(OR(L26="",M26="",J26=""),"", IF(L26="Y", IF(M26<=J26,"Y","N"), IF(M26<=DATE(YEAR(J26),3,31),"Y","N") )) | O26: =IF(OR(C26="", B26=""), "", INDEX(RentTable, MATCH(B26, {0,1,2,3,4}, 0), MATCH(C26, {20,30,40,50,60,70,80}, 1)) ) | Q26: =IF(OR(O26="", ISBLANK(O26), O26=0), "", O26 - P26) | T26: =IF(OR(R26=""), "", R26 + S26) | U26: {=_xlfn.IFS(OR(Q26="", T26="", Q26=0, "", T26=0), "", AND(T26<=Q26,D26<=Q26), "Y", OR(T26>Q26,D26>Q26), "N")}
H27: {=IF(OR(F27="", G27=""), "", _xlfn.LET( _xlpm.rowIndex, MATCH(F27, INDEX(IncomeTable,,1), 0), _xlpm.thresholds, INDEX(IncomeTable, _xlpm.rowIndex, 2):INDEX(IncomeTable, _xlpm.rowIndex, 8), _xlpm.labels, {20,30,40,50,60,70,80}, _xlpm.income, G27, IF(_xlpm.income < INDEX(_xlpm.thresholds,1), "Below 20%", IF(_xlpm.income > INDEX(_xlpm.thresholds,7), "Above 80%", INDEX(_xlpm.labels, _xlfn.XLOOKUP(_xlpm.income, _xlpm.thresholds, _xlfn.SEQUENCE(1,7), , -1)) ) ) ) )} | I27: =IF(AND(ISNUMBER(C27), ISNUMBER(H27)), IF(C27=H27, "Y", "N"), "") | N27: =IF(OR(L27="",M27="",J27=""),"", IF(L27="Y", IF(M27<=J27,"Y","N"), IF(M27<=DATE(YEAR(J27),3,31),"Y","N") )) | O27: =IF(OR(C27="", B27=""), "", INDEX(RentTable, MATCH(B27, {0,1,2,3,4}, 0), MATCH(C27, {20,30,40,50,60,70,80}, 1)) ) | Q27: =IF(OR(O27="", ISBLANK(O27), O27=0), "", O27 - P27) | T27: =IF(OR(R27=""), "", R27 + S27) | U27: {=_xlfn.IFS(OR(Q27="", T27="", Q27=0, "", T27=0), "", AND(T27<=Q27,D27<=Q27), "Y", OR(T27>Q27,D27>Q27), "N")}
H28: {=IF(OR(F28="", G28=""), "", _xlfn.LET( _xlpm.rowIndex, MATCH(F28, INDEX(IncomeTable,,1), 0), _xlpm.thresholds, INDEX(IncomeTable, _xlpm.rowIndex, 2):INDEX(IncomeTable, _xlpm.rowIndex, 8), _xlpm.labels, {20,30,40,50,60,70,80}, _xlpm.income, G28, IF(_xlpm.income < INDEX(_xlpm.thresholds,1), "Below 20%", IF(_xlpm.income > INDEX(_xlpm.thresholds,7), "Above 80%", INDEX(_xlpm.labels, _xlfn.XLOOKUP(_xlpm.income, _xlpm.thresholds, _xlfn.SEQUENCE(1,7), , -1)) ) ) ) )} | I28: =IF(AND(ISNUMBER(C28), ISNUMBER(H28)), IF(C28=H28, "Y", "N"), "") | N28: =IF(OR(L28="",M28="",J28=""),"", IF(L28="Y", IF(M28<=J28,"Y","N"), IF(M28<=DATE(YEAR(J28),3,31),"Y","N") )) | O28: =IF(OR(C28="", B28=""), "", INDEX(RentTable, MATCH(B28, {0,1,2,3,4}, 0), MATCH(C28, {20,30,40,50,60,70,80}, 1)) ) | Q28: =IF(OR(O28="", ISBLANK(O28), O28=0), "", O28 - P28) | T28: =IF(OR(R28=""), "", R28 + S28) | U28: {=_xlfn.IFS(OR(Q28="", T28="", Q28=0, "", T28=0), "", AND(T28<=Q28,D28<=Q28), "Y", OR(T28>Q28,D28>Q28), "N")}
H29: {=IF(OR(F29="", G29=""), "", _xlfn.LET( _xlpm.rowIndex, MATCH(F29, INDEX(IncomeTable,,1), 0), _xlpm.thresholds, INDEX(IncomeTable, _xlpm.rowIndex, 2):INDEX(IncomeTable, _xlpm.rowIndex, 8), _xlpm.labels, {20,30,40,50,60,70,80}, _xlpm.income, G29, IF(_xlpm.income < INDEX(_xlpm.thresholds,1), "Below 20%", IF(_xlpm.income > INDEX(_xlpm.thresholds,7), "Above 80%", INDEX(_xlpm.labels, _xlfn.XLOOKUP(_xlpm.income, _xlpm.thresholds, _xlfn.SEQUENCE(1,7), , -1)) ) ) ) )} | I29: =IF(AND(ISNUMBER(C29), ISNUMBER(H29)), IF(C29=H29, "Y", "N"), "") | N29: =IF(OR(L29="",M29="",J29=""),"", IF(L29="Y", IF(M29<=J29,"Y","N"), IF(M29<=DATE(YEAR(J29),3,31),"Y","N") )) | O29: =IF(OR(C29="", B29=""), "", INDEX(RentTable, MATCH(B29, {0,1,2,3,4}, 0), MATCH(C29, {20,30,40,50,60,70,80}, 1)) ) | Q29: =IF(OR(O29="", ISBLANK(O29), O29=0), "", O29 - P29) | T29: =IF(OR(R29=""), "", R29 + S29) | U29: {=_xlfn.IFS(OR(Q29="", T29="", Q29=0, "", T29=0), "", AND(T29<=Q29,D29<=Q29), "Y", OR(T29>Q29,D29>Q29), "N")}
H30: {=IF(OR(F30="", G30=""), "", _xlfn.LET( _xlpm.rowIndex, MATCH(F30, INDEX(IncomeTable,,1), 0), _xlpm.thresholds, INDEX(IncomeTable, _xlpm.rowIndex, 2):INDEX(IncomeTable, _xlpm.rowIndex, 8), _xlpm.labels, {20,30,40,50,60,70,80}, _xlpm.income, G30, IF(_xlpm.income < INDEX(_xlpm.thresholds,1), "Below 20%", IF(_xlpm.income > INDEX(_xlpm.thresholds,7), "Above 80%", INDEX(_xlpm.labels, _xlfn.XLOOKUP(_xlpm.income, _xlpm.thresholds, _xlfn.SEQUENCE(1,7), , -1)) ) ) ) )} | I30: =IF(AND(ISNUMBER(C30), ISNUMBER(H30)), IF(C30=H30, "Y", "N"), "") | N30: =IF(OR(L30="",M30="",J30=""),"", IF(L30="Y", IF(M30<=J30,"Y","N"), IF(M30<=DATE(YEAR(J30),3,31),"Y","N") )) | O30: =IF(OR(C30="", B30=""), "", INDEX(RentTable, MATCH(B30, {0,1,2,3,4}, 0), MATCH(C30, {20,30,40,50,60,70,80}, 1)) ) | Q30: =IF(OR(O30="", ISBLANK(O30), O30=0), "", O30 - P30) | T30: =IF(OR(R30=""), "", R30 + S30) | U30: {=_xlfn.IFS(OR(Q30="", T30="", Q30=0, "", T30=0), "", AND(T30<=Q30,D30<=Q30), "Y", OR(T30>Q30,D30>Q30), "N")}
H31: {=IF(OR(F31="", G31=""), "", _xlfn.LET( _xlpm.rowIndex, MATCH(F31, INDEX(IncomeTable,,1), 0), _xlpm.thresholds, INDEX(IncomeTable, _xlpm.rowIndex, 2):INDEX(IncomeTable, _xlpm.rowIndex, 8), _xlpm.labels, {20,30,40,50,60,70,80}, _xlpm.income, G31, IF(_xlpm.income < INDEX(_xlpm.thresholds,1), "Below 20%", IF(_xlpm.income > INDEX(_xlpm.thresholds,7), "Above 80%", INDEX(_xlpm.labels, _xlfn.XLOOKUP(_xlpm.income, _xlpm.thresholds, _xlfn.SEQUENCE(1,7), , -1)) ) ) ) )} | I31: =IF(AND(ISNUMBER(C31), ISNUMBER(H31)), IF(C31=H31, "Y", "N"), "") | N31: =IF(OR(L31="",M31="",J31=""),"", IF(L31="Y", IF(M31<=J31,"Y","N"), IF(M31<=DATE(YEAR(J31),3,31),"Y","N") )) | O31: =IF(OR(C31="", B31=""), "", INDEX(RentTable, MATCH(B31, {0,1,2,3,4}, 0), MATCH(C31, {20,30,40,50,60,70,80}, 1)) ) | Q31: =IF(OR(O31="", ISBLANK(O31), O31=0), "", O31 - P31) | T31: =IF(OR(R31=""), "", R31 + S31) | U31: {=_xlfn.IFS(OR(Q31="", T31="", Q31=0, "", T31=0), "", AND(T31<=Q31,D31<=Q31), "Y", OR(T31>Q31,D31>Q31), "N")}
H32: {=IF(OR(F32="", G32=""), "", _xlfn.LET( _xlpm.rowIndex, MATCH(F32, INDEX(IncomeTable,,1), 0), _xlpm.thresholds, INDEX(IncomeTable, _xlpm.rowIndex, 2):INDEX(IncomeTable, _xlpm.rowIndex, 8), _xlpm.labels, {20,30,40,50,60,70,80}, _xlpm.income, G32, IF(_xlpm.income < INDEX(_xlpm.thresholds,1), "Below 20%", IF(_xlpm.income > INDEX(_xlpm.thresholds,7), "Above 80%", INDEX(_xlpm.labels, _xlfn.XLOOKUP(_xlpm.income, _xlpm.thresholds, _xlfn.SEQUENCE(1,7), , -1)) ) ) ) )} | I32: =IF(AND(ISNUMBER(C32), ISNUMBER(H32)), IF(C32=H32, "Y", "N"), "") | N32: =IF(OR(L32="",M32="",J32=""),"", IF(L32="Y", IF(M32<=J32,"Y","N"), IF(M32<=DATE(YEAR(J32),3,31),"Y","N") )) | O32: =IF(OR(C32="", B32=""), "", INDEX(RentTable, MATCH(B32, {0,1,2,3,4}, 0), MATCH(C32, {20,30,40,50,60,70,80}, 1)) ) | Q32: =IF(OR(O32="", ISBLANK(O32), O32=0), "", O32 - P32) | T32: =IF(OR(R32=""), "", R32 + S32) | U32: {=_xlfn.IFS(OR(Q32="", T32="", Q32=0, "", T32=0), "", AND(T32<=Q32,D32<=Q32), "Y", OR(T32>Q32,D32>Q32), "N")}
H33: {=IF(OR(F33="", G33=""), "", _xlfn.LET( _xlpm.rowIndex, MATCH(F33, INDEX(IncomeTable,,1), 0), _xlpm.thresholds, INDEX(IncomeTable, _xlpm.rowIndex, 2):INDEX(IncomeTable, _xlpm.rowIndex, 8), _xlpm.labels, {20,30,40,50,60,70,80}, _xlpm.income, G33, IF(_xlpm.income < INDEX(_xlpm.thresholds,1), "Below 20%", IF(_xlpm.income > INDEX(_xlpm.thresholds,7), "Above 80%", INDEX(_xlpm.labels, _xlfn.XLOOKUP(_xlpm.income, _xlpm.thresholds, _xlfn.SEQUENCE(1,7), , -1)) ) ) ) )} | I33: =IF(AND(ISNUMBER(C33), ISNUMBER(H33)), IF(C33=H33, "Y", "N"), "") | N33: =IF(OR(L33="",M33="",J33=""),"", IF(L33="Y", IF(M33<=J33,"Y","N"), IF(M33<=DATE(YEAR(J33),3,31),"Y","N") )) | O33: =IF(OR(C33="", B33=""), "", INDEX(RentTable, MATCH(B33, {0,1,2,3,4}, 0), MATCH(C33, {20,30,40,50,60,70,80}, 1)) ) | Q33: =IF(OR(O33="", ISBLANK(O33), O33=0), "", O33 - P33) | T33: =IF(OR(R33=""), "", R33 + S33) | U33: {=_xlfn.IFS(OR(Q33="", T33="", Q33=0, "", T33=0), "", AND(T33<=Q33,D33<=Q33), "Y", OR(T33>Q33,D33>Q33), "N")}
H34: {=IF(OR(F34="", G34=""), "", _xlfn.LET( _xlpm.rowIndex, MATCH(F34, INDEX(IncomeTable,,1), 0), _xlpm.thresholds, INDEX(IncomeTable, _xlpm.rowIndex, 2):INDEX(IncomeTable, _xlpm.rowIndex, 8), _xlpm.labels, {20,30,40,50,60,70,80}, _xlpm.income, G34, IF(_xlpm.income < INDEX(_xlpm.thresholds,1), "Below 20%", IF(_xlpm.income > INDEX(_xlpm.thresholds,7), "Above 80%", INDEX(_xlpm.labels, _xlfn.XLOOKUP(_xlpm.income, _xlpm.thresholds, _xlfn.SEQUENCE(1,7), , -1)) ) ) ) )} | I34: =IF(AND(ISNUMBER(C34), ISNUMBER(H34)), IF(C34=H34, "Y", "N"), "") | N34: =IF(OR(L34="",M34="",J34=""),"", IF(L34="Y", IF(M34<=J34,"Y","N"), IF(M34<=DATE(YEAR(J34),3,31),"Y","N") )) | O34: =IF(OR(C34="", B34=""), "", INDEX(RentTable, MATCH(B34, {0,1,2,3,4}, 0), MATCH(C34, {20,30,40,50,60,70,80}, 1)) ) | Q34: =IF(OR(O34="", ISBLANK(O34), O34=0), "", O34 - P34) | T34: =IF(OR(R34=""), "", R34 + S34) | U34: {=_xlfn.IFS(OR(Q34="", T34="", Q34=0, "", T34=0), "", AND(T34<=Q34,D34<=Q34), "Y", OR(T34>Q34,D34>Q34), "N")}
... H227: {=IF(OR(F227="", G227=""), "", _xlfn.LET( _xlpm.rowIndex, MATCH(F227, INDEX(IncomeTable,,1), 0), _xlpm.thresholds, INDEX(IncomeTable, _xlpm.rowIndex, 2):INDEX(IncomeTable, _xlpm.rowIndex, 8), _xlpm.labels, {20,30,40,50,60,70,80}, _xlpm.income, G227, IF(_xlpm.income < INDEX(_xlpm.thresholds,1), "Below 20%", IF(_xlpm.income > INDEX(_xlpm.thresholds,7), "Above 80%", INDEX(_xlpm.labels, _xlfn.XLOOKUP(_xlpm.income, _xlpm.thresholds, _xlfn.SEQUENCE(1,7), , -1)) ) ) ) )} | I227: =IF(AND(ISNUMBER(C227), ISNUMBER(H227)), IF(C227=H227, "Y", "N"), "") | N227: =IF(OR(L227="",M227="",J227=""),"", IF(L227="Y", IF(M227<=J227,"Y","N"), IF(M227<=DATE(YEAR(J227),3,31),"Y","N") )) | O227: =IF(OR(C227="", B227=""), "", INDEX(RentTable, MATCH(B227, {0,1,2,3,4}, 0), MATCH(C227, {20,30,40,50,60,70,80}, 1)) ) | Q227: =IF(OR(O227="", ISBLANK(O227), O227=0), "", O227 - P227) | T227: =IF(OR(R227=""), "", R227 + S227) | U227: {=_xlfn.IFS(OR(Q227="", T227="", Q227=0, "", T227=0), "", AND(T227<=Q227,D227<=Q227), "Y", OR(T227>Q227,D227>Q227), "N")}
H228: {=IF(OR(F228="", G228=""), "", _xlfn.LET( _xlpm.rowIndex, MATCH(F228, INDEX(IncomeTable,,1), 0), _xlpm.thresholds, INDEX(IncomeTable, _xlpm.rowIndex, 2):INDEX(IncomeTable, _xlpm.rowIndex, 8), _xlpm.labels, {20,30,40,50,60,70,80}, _xlpm.income, G228, IF(_xlpm.income < INDEX(_xlpm.thresholds,1), "Below 20%", IF(_xlpm.income > INDEX(_xlpm.thresholds,7), "Above 80%", INDEX(_xlpm.labels, _xlfn.XLOOKUP(_xlpm.income, _xlpm.thresholds, _xlfn.SEQUENCE(1,7), , -1)) ) ) ) )} | I228: =IF(AND(ISNUMBER(C228), ISNUMBER(H228)), IF(C228=H228, "Y", "N"), "") | N228: =IF(OR(L228="", M228="", J228=""),"", IF(L228="Y", IF(M228<J228, "Y", "N"), IF(M228<=DATE(YEAR(J228),3,31), "Y", "N") )) | O228: =IF(OR(C228="", B228=""), "", INDEX(RentTable, MATCH(B228, {0,1,2,3,4}, 0), MATCH(C228, {20,30,40,50,60,70,80}, 1)) ) | Q228: =IF(OR(O228="", ISBLANK(O228), O228=0), "", O228 - P228) | T228: =IF(OR(R228=""), "", R228 + S228) | U228: {=_xlfn.IFS(OR(Q228="", T228="", Q228=0, "", T228=0), "", AND(T228<=Q228,D228<=Q228), "Y", OR(T228>Q228,D228>Q228), "N")}
H229: {=IF(OR(F229="", G229=""), "", _xlfn.LET( _xlpm.rowIndex, MATCH(F229, INDEX(IncomeTable,,1), 0), _xlpm.thresholds, INDEX(IncomeTable, _xlpm.rowIndex, 2):INDEX(IncomeTable, _xlpm.rowIndex, 8), _xlpm.labels, {20,30,40,50,60,70,80}, _xlpm.income, G229, IF(_xlpm.income < INDEX(_xlpm.thresholds,1), "Below 20%", IF(_xlpm.income > INDEX(_xlpm.thresholds,7), "Above 80%", INDEX(_xlpm.labels, _xlfn.XLOOKUP(_xlpm.income, _xlpm.thresholds, _xlfn.SEQUENCE(1,7), , -1)) ) ) ) )} | I229: =IF(AND(ISNUMBER(C229), ISNUMBER(H229)), IF(C229=H229, "Y", "N"), "") | N229: =IF(OR(L229="", M229="", J229=""),"", IF(L229="Y", IF(M229<J229, "Y", "N"), IF(M229<=DATE(YEAR(J229),3,31), "Y", "N") )) | O229: =IF(OR(C229="", B229=""), "", INDEX(RentTable, MATCH(B229, {0,1,2,3,4}, 0), MATCH(C229, {20,30,40,50,60,70,80}, 1)) ) | Q229: =IF(OR(O229="", ISBLANK(O229), O229=0), "", O229 - P229) | T229: =IF(OR(R229=""), "", R229 + S229) | U229: {=_xlfn.IFS(OR(Q229="", T229="", Q229=0, "", T229=0), "", AND(T229<=Q229,D229<=Q229), "Y", OR(T229>Q229,D229>Q229), "N")}
H230: {=IF(OR(F230="", G230=""), "", _xlfn.LET( _xlpm.rowIndex, MATCH(F230, INDEX(IncomeTable,,1), 0), _xlpm.thresholds, INDEX(IncomeTable, _xlpm.rowIndex, 2):INDEX(IncomeTable, _xlpm.rowIndex, 8), _xlpm.labels, {20,30,40,50,60,70,80}, _xlpm.income, G230, IF(_xlpm.income < INDEX(_xlpm.thresholds,1), "Below 20%", IF(_xlpm.income > INDEX(_xlpm.thresholds,7), "Above 80%", INDEX(_xlpm.labels, _xlfn.XLOOKUP(_xlpm.income, _xlpm.thresholds, _xlfn.SEQUENCE(1,7), , -1)) ) ) ) )} | I230: =IF(AND(ISNUMBER(C230), ISNUMBER(H230)), IF(C230=H230, "Y", "N"), "") | N230: =IF(OR(L230="", M230="", J230=""),"", IF(L230="Y", IF(M230<J230, "Y", "N"), IF(M230<=DATE(YEAR(J230),3,31), "Y", "N") )) | O230: =IF(OR(C230="", B230=""), "", INDEX(RentTable, MATCH(B230, {0,1,2,3,4}, 0), MATCH(C230, {20,30,40,50,60,70,80}, 1)) ) | Q230: =IF(OR(O230="", ISBLANK(O230), O230=0), "", O230 - P230) | T230: =IF(OR(R230=""), "", R230 + S230) | U230: {=_xlfn.IFS(OR(Q230="", T230="", Q230=0, "", T230=0), "", AND(T230<=Q230,D230<=Q230), "Y", OR(T230>Q230,D230>Q230), "N")}
H231: {=IF(OR(F231="", G231=""), "", _xlfn.LET( _xlpm.rowIndex, MATCH(F231, INDEX(IncomeTable,,1), 0), _xlpm.thresholds, INDEX(IncomeTable, _xlpm.rowIndex, 2):INDEX(IncomeTable, _xlpm.rowIndex, 8), _xlpm.labels, {20,30,40,50,60,70,80}, _xlpm.income, G231, IF(_xlpm.income < INDEX(_xlpm.thresholds,1), "Below 20%", IF(_xlpm.income > INDEX(_xlpm.thresholds,7), "Above 80%", INDEX(_xlpm.labels, _xlfn.XLOOKUP(_xlpm.income, _xlpm.thresholds, _xlfn.SEQUENCE(1,7), , -1)) ) ) ) )} | I231: =IF(AND(ISNUMBER(C231), ISNUMBER(H231)), IF(C231=H231, "Y", "N"), "") | N231: =IF(OR(L231="", M231="", J231=""),"", IF(L231="Y", IF(M231<J231, "Y", "N"), IF(M231<=DATE(YEAR(J231),3,31), "Y", "N") )) | O231: =IF(OR(C231="", B231=""), "", INDEX(RentTable, MATCH(B231, {0,1,2,3,4}, 0), MATCH(C231, {20,30,40,50,60,70,80}, 1)) ) | Q231: =IF(OR(O231="", ISBLANK(O231), O231=0), "", O231 - P231) | T231: =IF(OR(R231=""), "", R231 + S231) | U231: {=_xlfn.IFS(OR(Q231="", T231="", Q231=0, "", T231=0), "", AND(T231<=Q231,D231<=Q231), "Y", OR(T231>Q231,D231>Q231), "N")}
H232: {=IF(OR(F232="", G232=""), "", _xlfn.LET( _xlpm.rowIndex, MATCH(F232, INDEX(IncomeTable,,1), 0), _xlpm.thresholds, INDEX(IncomeTable, _xlpm.rowIndex, 2):INDEX(IncomeTable, _xlpm.rowIndex, 8), _xlpm.labels, {20,30,40,50,60,70,80}, _xlpm.income, G232, IF(_xlpm.income < INDEX(_xlpm.thresholds,1), "Below 20%", IF(_xlpm.income > INDEX(_xlpm.thresholds,7), "Above 80%", INDEX(_xlpm.labels, _xlfn.XLOOKUP(_xlpm.income, _xlpm.thresholds, _xlfn.SEQUENCE(1,7), , -1)) ) ) ) )} | I232: =IF(AND(ISNUMBER(C232), ISNUMBER(H232)), IF(C232=H232, "Y", "N"), "") | N232: =IF(OR(L232="", M232="", J232=""),"", IF(L232="Y", IF(M232<J232, "Y", "N"), IF(M232<=DATE(YEAR(J232),3,31), "Y", "N") )) | O232: =IF(OR(C232="", B232=""), "", INDEX(RentTable, MATCH(B232, {0,1,2,3,4}, 0), MATCH(C232, {20,30,40,50,60,70,80}, 1)) ) | Q232: =IF(OR(O232="", ISBLANK(O232), O232=0), "", O232 - P232) | T232: =IF(OR(R232=""), "", R232 + S232) | U232: {=_xlfn.IFS(OR(Q232="", T232="", Q232=0, "", T232=0), "", AND(T232<=Q232,D232<=Q232), "Y", OR(T232>Q232,D232>Q232), "N")}
H233: {=IF(OR(F233="", G233=""), "", _xlfn.LET( _xlpm.rowIndex, MATCH(F233, INDEX(IncomeTable,,1), 0), _xlpm.thresholds, INDEX(IncomeTable, _xlpm.rowIndex, 2):INDEX(IncomeTable, _xlpm.rowIndex, 8), _xlpm.labels, {20,30,40,50,60,70,80}, _xlpm.income, G233, IF(_xlpm.income < INDEX(_xlpm.thresholds,1), "Below 20%", IF(_xlpm.income > INDEX(_xlpm.thresholds,7), "Above 80%", INDEX(_xlpm.labels, _xlfn.XLOOKUP(_xlpm.income, _xlpm.thresholds, _xlfn.SEQUENCE(1,7), , -1)) ) ) ) )} | I233: =IF(AND(ISNUMBER(C233), ISNUMBER(H233)), IF(C233=H233, "Y", "N"), "") | N233: =IF(OR(L233="", M233="", J233=""),"", IF(L233="Y", IF(M233<J233, "Y", "N"), IF(M233<=DATE(YEAR(J233),3,31), "Y", "N") )) | O233: =IF(OR(C233="", B233=""), "", INDEX(RentTable, MATCH(B233, {0,1,2,3,4}, 0), MATCH(C233, {20,30,40,50,60,70,80}, 1)) ) | Q233: =IF(OR(O233="", ISBLANK(O233), O233=0), "", O233 - P233) | T233: =IF(OR(R233=""), "", R233 + S233) | U233: {=_xlfn.IFS(OR(Q233="", T233="", Q233=0, "", T233=0), "", AND(T233<=Q233,D233<=Q233), "Y", OR(T233>Q233,D233>Q233), "N")}
H234: {=IF(OR(F234="", G234=""), "", _xlfn.LET( _xlpm.rowIndex, MATCH(F234, INDEX(IncomeTable,,1), 0), _xlpm.thresholds, INDEX(IncomeTable, _xlpm.rowIndex, 2):INDEX(IncomeTable, _xlpm.rowIndex, 8), _xlpm.labels, {20,30,40,50,60,70,80}, _xlpm.income, G234, IF(_xlpm.income < INDEX(_xlpm.thresholds,1), "Below 20%", IF(_xlpm.income > INDEX(_xlpm.thresholds,7), "Above 80%", INDEX(_xlpm.labels, _xlfn.XLOOKUP(_xlpm.income, _xlpm.thresholds, _xlfn.SEQUENCE(1,7), , -1)) ) ) ) )} | I234: =IF(AND(ISNUMBER(C234), ISNUMBER(H234)), IF(C234=H234, "Y", "N"), "") | N234: =IF(OR(L234="", M234="", J234=""),"", IF(L234="Y", IF(M234<J234, "Y", "N"), IF(M234<=DATE(YEAR(J234),3,31), "Y", "N") )) | O234: =IF(OR(C234="", B234=""), "", INDEX(RentTable, MATCH(B234, {0,1,2,3,4}, 0), MATCH(C234, {20,30,40,50,60,70,80}, 1)) ) | Q234: =IF(OR(O234="", ISBLANK(O234), O234=0), "", O234 - P234) | T234: =IF(OR(R234=""), "", R234 + S234) | U234: {=_xlfn.IFS(OR(Q234="", T234="", Q234=0, "", T234=0), "", AND(T234<=Q234,D234<=Q234), "Y", OR(T234>Q234,D234>Q234), "N")}
H235: {=IF(OR(F235="", G235=""), "", _xlfn.LET( _xlpm.rowIndex, MATCH(F235, INDEX(IncomeTable,,1), 0), _xlpm.thresholds, INDEX(IncomeTable, _xlpm.rowIndex, 2):INDEX(IncomeTable, _xlpm.rowIndex, 8), _xlpm.labels, {20,30,40,50,60,70,80}, _xlpm.income, G235, IF(_xlpm.income < INDEX(_xlpm.thresholds,1), "Below 20%", IF(_xlpm.income > INDEX(_xlpm.thresholds,7), "Above 80%", INDEX(_xlpm.labels, _xlfn.XLOOKUP(_xlpm.income, _xlpm.thresholds, _xlfn.SEQUENCE(1,7), , -1)) ) ) ) )} | I235: =IF(AND(ISNUMBER(C235), ISNUMBER(H235)), IF(C235=H235, "Y", "N"), "") | N235: =IF(OR(L235="", M235="", J235=""),"", IF(L235="Y", IF(M235<J235, "Y", "N"), IF(M235<=DATE(YEAR(J235),3,31), "Y", "N") )) | O235: =IF(OR(C235="", B235=""), "", INDEX(RentTable, MATCH(B235, {0,1,2,3,4}, 0), MATCH(C235, {20,30,40,50,60,70,80}, 1)) ) | Q235: =IF(OR(O235="", ISBLANK(O235), O235=0), "", O235 - P235) | T235: =IF(OR(R235=""), "", R235 + S235) | U235: {=_xlfn.IFS(OR(Q235="", T235="", Q235=0, "", T235=0), "", AND(T235<=Q235,D235<=Q235), "Y", OR(T235>Q235,D235>Q235), "N")}
...

Sheet Virginia Housing Limits
A2: MSA: Richmond, VA HUD MSA
A4: 2024 Median Income Limit: $110,300
B6: Income Limits
A7: Household Size | B7: 0.2 | C7: 0.3 | D7: 0.4 | E7: 0.5 | F7: 0.6 | G7: 0.7 | H7: 0.8
A8: 1 | B8: =E8*0.4 -> 15460 | C8: =E8*0.6 -> 23190 | D8: =E8*0.8 -> 30920 | E8: 38650 | F8: =E8*1.2 -> 46380 | G8: =E8*1.4 -> 54110 | H8: =E8*1.6 -> 61840
A9: 2 | B9: =E9*0.4 -> 17660 | C9: =E9*0.6 -> 26490 | D9: =E9*0.8 -> 35320 | E9: 44150 | F9: =E9*1.2 -> 52980 | G9: =E9*1.4 -> 61810 | H9: =E9*1.6 -> 70640
A10: 3 | B10: =E10*0.4 -> 19860 | C10: =E10*0.6 -> 29790 | D10: =E10*0.8 -> 39720 | E10: 49650 | F10: =E10*1.2 -> 59580 | G10: =E10*1.4 -> 69510 | H10: =E10*1.6 -> 79440
A11: 4 | B11: =E11*0.4 -> 22060 | C11: =E11*0.6 -> 33090 | D11: =E11*0.8 -> 44120 | E11: 55150 | F11: =E11*1.2 -> 66180 | G11: =E11*1.4 -> 77210 | H11: =E11*1.6 -> 88240
A12: 5 | B12: =E12*0.4 -> 23840 | C12: =E12*0.6 -> 35760 | D12: =E12*0.8 -> 47680 | E12: 59600 | F12: =E12*1.2 -> 71520 | G12: =E12*1.4 -> 83440 | H12: =E12*1.6 -> 95360
A13: 6 | B13: =E13*0.4 -> 25600 | C13: =E13*0.6 -> 38400 | D13: =E13*0.8 -> 51200 | E13: 64000 | F13: =E13*1.2 -> 76800 | G13: =E13*1.4 -> 89600 | H13: =E13*1.6 -> 102400
A14: 7 | B14: =E14*0.4 -> 27360 | C14: =E14*0.6 -> 41040 | D14: =E14*0.8 -> 54720 | E14: 68400 | F14: =E14*1.2 -> 82080 | G14: =E14*1.4 -> 95760 | H14: =E14*1.6 -> 109440
A15: 8 | B15: =E15*0.4 -> 29120 | C15: =E15*0.6 -> 43680 | D15: =E15*0.8 -> 58240 | E15: 72800 | F15: =E15*1.2 -> 87360 | G15: =E15*1.4 -> 101920 | H15: =E15*1.6 -> 116480
B19: Monthly Rent Limits
A20: Bedroom Size | B20: 0.2 | C20: 0.3 | D20: 0.4 | E20: 0.5 | F20: 0.6 | G20: 0.7 | H20: 0.8
A21: 0 | B21: 386 | C21: 579 | D21: 773 | E21: 966 | F21: 1159 | G21: 1352 | H21: 1546
A22: 1 | B22: 414 | C22: 621 | D22: 828 | E22: 1035 | F22: 1242 | G22: 1449 | H22: 1656
A23: 2 | B23: 496 | C23: 744 | D23: 993 | E23: 1241 | F23: 1489 | G23: 1737 | H23: 1986
A24: 3 | B24: 573 | C24: 860 | D24: 1147 | E24: 1434 | F24: 1721 | G24: 2008 | H24: 2295
A25: 4 | B25: 640 | C25: 960 | D25: 1280 | E25: 1600 | F25: 1920 | G25: 2240 | H25: 2560
